{
    "color":"343434",
    "registryname": "melter",
    "localizedname": "Melter",
    "parts": [
        {
            "x": -1,
            "y": 0,
            "z": 1,
            "elements": [
                "immersiveengineering:metal_decoration0@1"
            ]
        },
        {
            "x": -2,
            "y": 0,
            "z": 2,
            "elements": [
                "modularmachinery:blockfluidoutputhatch"
            ]
        },
        {
            "x": -1,
            "y": 0,
            "z": 0,
            "elements": [
                "tconstruct:seared@3"
            ]
        },
        {
            "x": -1,
            "y": 0,
            "z": 2,
            "elements": [
                "minecraft:glass@0"
            ]
        },
        {
            "x": 0,
            "y": 0,
            "z": 1,
            "elements": [
                "immersiveengineering:metal_decoration0@1"
            ]
        },
        {
            "x": -2,
            "y": 0,
            "z": 3,
            "elements": [
                "tconstruct:seared@3"
            ]
        },
        {
            "x": 1,
            "y": 0,
            "z": 0,
            
            "elements": [
                "tconstruct:seared@3"
            ]
        },
        {
            "x": 0,
            "y": 0,
            "z": 2,
            "elements": [
                "minecraft:glass@0"
            ]
        },
        {
            "x": -1,
            "y": 0,
            "z": 3,
            "elements": [
                "immersiveengineering:metal_decoration0@1"
            ]
        },
        {
            "x": 1,
            "y": 0,
            "z": 1,
            "elements": [
                "immersiveengineering:metal_decoration0@1"
            ]
        },
        {
            "x": 1,
            "y": 0,
            "z": 2,
            "elements": [
                "minecraft:glass@0"
            ]
        },
        {
            "x": 0,
            "y": 0,
            "z": 3,
            "elements": [
                "immersiveengineering:metal_decoration0@1"
            ]
        },
        {
            "x": -1,
            "y": 0,
            "z": 4,
            
            "elements": [
                "tconstruct:seared@3"
            ]
        },
        {
            "x": 2,
            "y": 0,
            "z": 1,
            
            "elements": [
                "tconstruct:seared@3"
            ]
        },
        {
            "x": 1,
            "y": 0,
            "z": 3,
            "elements": [
                "immersiveengineering:metal_decoration0@1"
            ]
        },
        {
            "x": 2,
            "y": 0,
            "z": 2,
            "elements": [
                "modularmachinery:blockinputbus"
            ]
        },
        {
            "x": 0,
            "y": 0,
            "z": 4,
            
            "elements": [
                "tconstruct:seared@3"
            ]
        },
        {
            "x": 1,
            "y": 0,
            "z": 4,
            
            "elements": [
                "tconstruct:seared@3"
            ]
        },
        {
            "x": 2,
            "y": 0,
            "z": 3,
            
            "elements": [
                "tconstruct:seared@3"
            ]
        },
        {
            "x": -1,
            "y": 1,
            "z": 1,
            
            "elements": [
                "tconstruct:seared_glass@0"
            ]
        },
        {
            "x": -1,
            "y": 1,
            "z": 2,
            
            "elements": [
                "tconstruct:seared_glass@0"
            ]
        },
        {
            "x": 0,
            "y": 1,
            "z": 1,
            
            "elements": [
                "tconstruct:seared_glass@0"
            ]
        },
        {
            "x": -1,
            "y": -1,
            "z": 1,
            
            "elements": [
                "tconstruct:seared@3"
            ]
        },
        {
            "x": -1,
            "y": 1,
            "z": 3,
            
            "elements": [
                "tconstruct:seared_glass@0"
            ]
        },
        {
            "x": 1,
            "y": 1,
            "z": 1,
            
            "elements": [
                "tconstruct:seared_glass@0"
            ]
        },
        {
            "x": 0,
            "y": 1,
            "z": 2,
            
            "elements": [
                "modularmachinery:blockenergyinputhatch"
            ]
        },
        {
            "x": -1,
            "y": -1,
            "z": 2,
            
            "elements": [
                "tconstruct:seared@3"
            ]
        },
        {
            "x": 0,
            "y": -1,
            "z": 1,
            
            "elements": [
                "tconstruct:seared@3"
            ]
        },
        {
            "x": 1,
            "y": 1,
            "z": 2,
            
            "elements": [
                "tconstruct:seared_glass@0"
            ]
        },
        {
            "x": 0,
            "y": 1,
            "z": 3,
            
            "elements": [
                "tconstruct:seared_glass@0"
            ]
        },
        {
            "x": -1,
            "y": -1,
            "z": 3,
            
            "elements": [
                "tconstruct:seared@3"
            ]
        },
        {
            "x": 0,
            "y": -1,
            "z": 2,
            
            "elements": [
                "tconstruct:seared@3"
            ]
        },
        {
            "x": 1,
            "y": -1,
            "z": 1,
            
            "elements": [
                "tconstruct:seared@3"
            ]
        },
        {
            "x": 1,
            "y": 1,
            "z": 3,
            
            "elements": [
                "tconstruct:seared_glass@0"
            ]
        },
        {
            "x": 0,
            "y": -1,
            "z": 3,
            
            "elements": [
                "tconstruct:seared@3"
            ]
        },
        {
            "x": 1,
            "y": -1,
            "z": 2,
            
            "elements": [
                "tconstruct:seared@3"
            ]
        },
        {
            "x": 1,
            "y": -1,
            "z": 3,
            
            "elements": [
                "tconstruct:seared@3"
            ]
        },
        {
            "x": -2,
            "y": 0,
            "z": 1,
            "elements": [
                "tconstruct:seared@3"
            ]
        }
    ]}