{
    "parts": [
        {
            "x": -1,
            "y": 0,
            "z": 1,
            "elements": [
                "immersiveengineering:metal_decoration0@1"
            ]
        },
        {
            "x": -2,
            "y": 0,
            "z": 2,
            "nbt": {"input":"0b","size":"5","casingColor":"16730368","id":"minecraft:tilefluidoutputhatch","tank":{"Empty":""}},
            "elements": [
                "modularmachinery:blockfluidoutputhatch@5"
            ]
        },
        {
            "x": -1,
            "y": 0,
            "z": 0,
            "nbt": {"hasMaster":"0b","id":"minecraft:tconstruct.smeltery_component"},
            "elements": [
                "tconstruct:seared@3"
            ]
        },
        {
            "x": -1,
            "y": 0,
            "z": 2,
            "elements": [
                "minecraft:glass@0"
            ]
        },
        {
            "x": 0,
            "y": 0,
            "z": 1,
            "elements": [
                "immersiveengineering:metal_decoration0@1"
            ]
        },
        {
            "x": -2,
            "y": 0,
            "z": 3,
            "nbt": {"hasMaster":"0b","id":"minecraft:tconstruct.smeltery_component"},
            "elements": [
                "tconstruct:seared@3"
            ]
        },
        {
            "x": 1,
            "y": 0,
            "z": 0,
            "nbt": {"hasMaster":"0b","id":"minecraft:tconstruct.smeltery_component"},
            "elements": [
                "tconstruct:seared@3"
            ]
        },
        {
            "x": 0,
            "y": 0,
            "z": 2,
            "elements": [
                "minecraft:glass@0"
            ]
        },
        {
            "x": -1,
            "y": 0,
            "z": 3,
            "elements": [
                "immersiveengineering:metal_decoration0@1"
            ]
        },
        {
            "x": 1,
            "y": 0,
            "z": 1,
            "elements": [
                "immersiveengineering:metal_decoration0@1"
            ]
        },
        {
            "x": 1,
            "y": 0,
            "z": 2,
            "elements": [
                "minecraft:glass@0"
            ]
        },
        {
            "x": 0,
            "y": 0,
            "z": 3,
            "elements": [
                "immersiveengineering:metal_decoration0@1"
            ]
        },
        {
            "x": -1,
            "y": 0,
            "z": 4,
            "nbt": {"hasMaster":"0b","id":"minecraft:tconstruct.smeltery_component"},
            "elements": [
                "tconstruct:seared@3"
            ]
        },
        {
            "x": 2,
            "y": 0,
            "z": 1,
            "nbt": {"hasMaster":"0b","id":"minecraft:tconstruct.smeltery_component"},
            "elements": [
                "tconstruct:seared@3"
            ]
        },
        {
            "x": 1,
            "y": 0,
            "z": 3,
            "elements": [
                "immersiveengineering:metal_decoration0@1"
            ]
        },
        {
            "x": 2,
            "y": 0,
            "z": 2,
            "nbt": {"busSize":"1","casingColor":"16730368","id":"minecraft:tileiteminputbus","inventory":{"inventoryArray":[{"holderEmpty":"1b","holderId":"0"},{"holderEmpty":"1b","holderId":"1"},{"holderEmpty":"1b","holderId":"2"},{"holderEmpty":"1b","holderId":"3"}],"outSlots":,"miscSlots":,"inSlots":,"sides":}},
            "elements": [
                "modularmachinery:blockinputbus@1"
            ]
        },
        {
            "x": 0,
            "y": 0,
            "z": 4,
            "nbt": {"hasMaster":"0b","id":"minecraft:tconstruct.smeltery_component"},
            "elements": [
                "tconstruct:seared@3"
            ]
        },
        {
            "x": 1,
            "y": 0,
            "z": 4,
            "nbt": {"hasMaster":"0b","id":"minecraft:tconstruct.smeltery_component"},
            "elements": [
                "tconstruct:seared@3"
            ]
        },
        {
            "x": 2,
            "y": 0,
            "z": 3,
            "nbt": {"hasMaster":"0b","id":"minecraft:tconstruct.smeltery_component"},
            "elements": [
                "tconstruct:seared@3"
            ]
        },
        {
            "x": -1,
            "y": 1,
            "z": 1,
            "nbt": {"hasMaster":"0b","id":"minecraft:tconstruct.smeltery_component"},
            "elements": [
                "tconstruct:seared_glass@0"
            ]
        },
        {
            "x": -1,
            "y": 1,
            "z": 2,
            "nbt": {"hasMaster":"0b","id":"minecraft:tconstruct.smeltery_component"},
            "elements": [
                "tconstruct:seared_glass@0"
            ]
        },
        {
            "x": 0,
            "y": 1,
            "z": 1,
            "nbt": {"hasMaster":"0b","id":"minecraft:tconstruct.smeltery_component"},
            "elements": [
                "tconstruct:seared_glass@0"
            ]
        },
        {
            "x": -1,
            "y": -1,
            "z": 1,
            "nbt": {"hasMaster":"0b","id":"minecraft:tconstruct.smeltery_component"},
            "elements": [
                "tconstruct:seared@3"
            ]
        },
        {
            "x": -1,
            "y": 1,
            "z": 3,
            "nbt": {"hasMaster":"0b","id":"minecraft:tconstruct.smeltery_component"},
            "elements": [
                "tconstruct:seared_glass@0"
            ]
        },
        {
            "x": 1,
            "y": 1,
            "z": 1,
            "nbt": {"hasMaster":"0b","id":"minecraft:tconstruct.smeltery_component"},
            "elements": [
                "tconstruct:seared_glass@0"
            ]
        },
        {
            "x": 0,
            "y": 1,
            "z": 2,
            "nbt": {"hatchSize":"3","casingColor":"16730368","id":"minecraft:tileenergyinputhatch","energy":"0L"},
            "elements": [
                "modularmachinery:blockenergyinputhatch@3"
            ]
        },
        {
            "x": -1,
            "y": -1,
            "z": 2,
            "nbt": {"hasMaster":"0b","id":"minecraft:tconstruct.smeltery_component"},
            "elements": [
                "tconstruct:seared@3"
            ]
        },
        {
            "x": 0,
            "y": -1,
            "z": 1,
            "nbt": {"hasMaster":"0b","id":"minecraft:tconstruct.smeltery_component"},
            "elements": [
                "tconstruct:seared@3"
            ]
        },
        {
            "x": 1,
            "y": 1,
            "z": 2,
            "nbt": {"hasMaster":"0b","id":"minecraft:tconstruct.smeltery_component"},
            "elements": [
                "tconstruct:seared_glass@0"
            ]
        },
        {
            "x": 0,
            "y": 1,
            "z": 3,
            "nbt": {"hasMaster":"0b","id":"minecraft:tconstruct.smeltery_component"},
            "elements": [
                "tconstruct:seared_glass@0"
            ]
        },
        {
            "x": -1,
            "y": -1,
            "z": 3,
            "nbt": {"hasMaster":"0b","id":"minecraft:tconstruct.smeltery_component"},
            "elements": [
                "tconstruct:seared@3"
            ]
        },
        {
            "x": 0,
            "y": -1,
            "z": 2,
            "nbt": {"hasMaster":"0b","id":"minecraft:tconstruct.smeltery_component"},
            "elements": [
                "tconstruct:seared@3"
            ]
        },
        {
            "x": 1,
            "y": -1,
            "z": 1,
            "nbt": {"hasMaster":"0b","id":"minecraft:tconstruct.smeltery_component"},
            "elements": [
                "tconstruct:seared@3"
            ]
        },
        {
            "x": 1,
            "y": 1,
            "z": 3,
            "nbt": {"hasMaster":"0b","id":"minecraft:tconstruct.smeltery_component"},
            "elements": [
                "tconstruct:seared_glass@0"
            ]
        },
        {
            "x": 0,
            "y": -1,
            "z": 3,
            "nbt": {"hasMaster":"0b","id":"minecraft:tconstruct.smeltery_component"},
            "elements": [
                "tconstruct:seared@3"
            ]
        },
        {
            "x": 1,
            "y": -1,
            "z": 2,
            "nbt": {"hasMaster":"0b","id":"minecraft:tconstruct.smeltery_component"},
            "elements": [
                "tconstruct:seared@3"
            ]
        },
        {
            "x": 1,
            "y": -1,
            "z": 3,
            "nbt": {"hasMaster":"0b","id":"minecraft:tconstruct.smeltery_component"},
            "elements": [
                "tconstruct:seared@3"
            ]
        },
        {
            "x": -2,
            "y": 0,
            "z": 1,
            "nbt": {"hasMaster":"0b","id":"minecraft:tconstruct.smeltery_component"},
            "elements": [
                "tconstruct:seared@3"
            ]
        }
    ]}